
Saving Model At: save_model/best_model.pth
Saving Model At: save_model/best_model.pth
Saving Model At: save_model/best_model.pth
Saving Model At: save_model/best_model.pth
Saving Model At: save_model/best_model.pth
Saving Model At: save_model/best_model.pth
Saving Model At: save_model/best_model.pth
Saving Model At: save_model/best_model.pth
Saving Model At: save_model/best_model.pth
Saving Model At: save_model/best_model.pth
Saving Model At: save_model/best_model.pth
Saving Model At: save_model/best_model.pth
Saving Model At: save_model/best_model.pth
Saving Model At: save_model/best_model.pth
Saving Model At: save_model/best_model.pth
Saving Model At: save_model/best_model.pth
Saving Model At: save_model/best_model.pth
Saving Model At: save_model/best_model.pth
Saving Model At: save_model/best_model.pth
[LOG]: Login Succesfull.
wandb: WARNING Calling wandb.login() after wandb.init() has no effect.
[W 2023-10-31 17:35:16,857] Trial 0 failed with parameters: {'lr': 3.4274903008423467e-07, 'n_estimators': 38, 'optimizer': 'Adam'} because of the following error: AttributeError("'torch.return_types.max' object has no attribute 'to'").
Traceback (most recent call last):
  File "/opt/conda/envs/env/lib/python3.8/site-packages/optuna/study/_optimize.py", line 200, in _run_trial
    value_or_values = func(trial)
  File "hyperpara.py", line 68, in objective
    val_loss, val_acc = engine.validation(model = model, dataloader = data.valid_dataloader, loss_fn = loss_fn,
  File "/jash/Workspace/Food/engine.py", line 151, in validation
    log_image_table(x_val, torch.max(logits.data, 1), y_val, logits.softmax(dim=1))
  File "/jash/Workspace/Food/engine.py", line 110, in log_image_table
    for img, pred, targ, prob in zip(images.to("cpu"), predicted.to("cpu"), labels.to("cpu"), probs.to("cpu")):
AttributeError: 'torch.return_types.max' object has no attribute 'to'
[W 2023-10-31 17:35:16,858] Trial 0 failed with value None.
Traceback (most recent call last):
  File "hyperpara.py", line 110, in <module>
    study.optimize(objective, n_trials=11)
  File "/opt/conda/envs/env/lib/python3.8/site-packages/optuna/study/study.py", line 451, in optimize
    _optimize(
  File "/opt/conda/envs/env/lib/python3.8/site-packages/optuna/study/_optimize.py", line 66, in _optimize
    _optimize_sequential(
  File "/opt/conda/envs/env/lib/python3.8/site-packages/optuna/study/_optimize.py", line 163, in _optimize_sequential
    frozen_trial = _run_trial(study, func, catch)
  File "/opt/conda/envs/env/lib/python3.8/site-packages/optuna/study/_optimize.py", line 251, in _run_trial
    raise func_err
  File "/opt/conda/envs/env/lib/python3.8/site-packages/optuna/study/_optimize.py", line 200, in _run_trial
    value_or_values = func(trial)
  File "hyperpara.py", line 68, in objective
    val_loss, val_acc = engine.validation(model = model, dataloader = data.valid_dataloader, loss_fn = loss_fn,
  File "/jash/Workspace/Food/engine.py", line 151, in validation
    log_image_table(x_val, torch.max(logits.data, 1), y_val, logits.softmax(dim=1))
  File "/jash/Workspace/Food/engine.py", line 110, in log_image_table
    for img, pred, targ, prob in zip(images.to("cpu"), predicted.to("cpu"), labels.to("cpu"), probs.to("cpu")):
AttributeError: 'torch.return_types.max' object has no attribute 'to'